INFO: 2019-06-26 05:39:48,385: perform_upgrade() 'Last run version was 0.7.2 or earlier, current version is 0.7.2'
INFO: 2019-06-26 05:39:48,497: process_command() 'Received command: []'
INFO: 2019-06-26 05:39:48,499: load_banned() 'Missing or invalid banned URLs list, no URLs will be banned'
INFO: 2019-06-26 05:39:48,509: load() 'Jumble loading'
INFO: 2019-06-26 05:39:48,510: _walk_modules() 'Jumble loading module in __init__ from /usr/share/variety/plugins/__init__.py'
INFO: 2019-06-26 05:39:48,511: _walk_modules() 'Jumble loading module in QuotationsPageSource from /usr/share/variety/plugins/quotes/QuotationsPageSource.py'
INFO: 2019-06-26 05:39:48,518: load() 'Jumble found plugin class: <class 'QuotationsPageSource.QuotationsPageSource'>: {'name': 'TheQuotationsPage.com', 'description': 'Fetches quotes from TheQuotationsPage.com', 'author': 'Peter Levi', 'version': '0.1'}'
INFO: 2019-06-26 05:39:48,519: _walk_modules() 'Jumble loading module in LocalFilesSource from /usr/share/variety/plugins/quotes/LocalFilesSource.py'
INFO: 2019-06-26 05:39:48,520: load() 'Jumble found plugin class: <class 'LocalFilesSource.LocalFilesSource'>: {'name': 'Local text files', 'description': 'Displays quotes, defined in local text files.\nPut your own txt files in: ~/.config/variety/pluginconfig/quotes/.\nThe file format is:\n\nquote -- author\n.\nsecond quote -- another author\n.\netc...\n\nExample: http://rvelthuis.de/zips/quotes.txt', 'author': 'Peter Levi', 'version': '0.1'}'
INFO: 2019-06-26 05:39:48,521: _walk_modules() 'Jumble loading module in __init__ from /usr/share/variety/plugins/quotes/__init__.py'
INFO: 2019-06-26 05:39:48,521: _walk_modules() 'Jumble loading module in GoodreadsSource from /usr/share/variety/plugins/quotes/GoodreadsSource.py'
INFO: 2019-06-26 05:39:48,522: load() 'Jumble found plugin class: <class 'GoodreadsSource.GoodreadsSource'>: {'name': 'Goodreads', 'description': 'Fetches quotes from Goodreads.com', 'author': 'Peter Levi', 'version': '0.1'}'
INFO: 2019-06-26 05:39:48,523: _walk_modules() 'Jumble loading module in QuotesDaddySource from /usr/share/variety/plugins/quotes/QuotesDaddySource.py'
INFO: 2019-06-26 05:39:48,523: load() 'Jumble found plugin class: <class 'QuotesDaddySource.QuotesDaddySource'>: {'name': 'QuotesDaddy', 'description': "Fetches quotes from QuotesDaddy's daily quotes RSS feed.\nDoes not support searching by tags or authors.", 'author': 'Peter Levi', 'version': '0.1'}'
INFO: 2019-06-26 05:39:48,525: reload_config() 'Creating new downloader for type 6, location Random wallpapers from Desktoppr.co'
INFO: 2019-06-26 05:39:48,526: reload_config() 'Creating new downloader for type 15, location Bing Photo of the Day'
INFO: 2019-06-26 05:39:48,526: reload_config() 'Creating new downloader for type 16, location High-resolution photos from Unsplash.com'
INFO: 2019-06-26 05:39:48,526: reload_config() 'Creating new downloader for type 8, location NASA's Astronomy Picture of the Day'
INFO: 2019-06-26 05:39:48,526: reload_config() 'Creating new downloader for type 7, location user:www.flickr.com/photos/peter-levi/;user_id:93647178@N00;'
INFO: 2019-06-26 05:39:48,526: log_options() 'Loaded options:'
INFO: 2019-06-26 05:39:48,526: log_options() 'change_enabled = False'
INFO: 2019-06-26 05:39:48,526: log_options() 'change_interval = 300'
INFO: 2019-06-26 05:39:48,526: log_options() 'change_on_start = False'
INFO: 2019-06-26 05:39:48,526: log_options() 'clipboard_enabled = False'
INFO: 2019-06-26 05:39:48,526: log_options() 'clipboard_hosts = ['wallhaven.cc', 'wallpapers.net', 'flickr.com', 'imgur.com', 'deviantart.com', 'interfacelift.com', 'vladstudio.com', 'imageshack.us', 'deviantart.net', 'imageshack.com']'
INFO: 2019-06-26 05:39:48,526: log_options() 'clipboard_use_whitelist = True'
INFO: 2019-06-26 05:39:48,526: log_options() 'clock_date_font = Ubuntu Condensed, 30'
INFO: 2019-06-26 05:39:48,526: log_options() 'clock_enabled = False'
INFO: 2019-06-26 05:39:48,526: log_options() 'clock_filter = -density 100 -font `fc-match -f '%{file[0]}' '%CLOCK_FONT_NAME'` -pointsize %CLOCK_FONT_SIZE -gravity SouthEast -fill '#00000044' -annotate 0x0+[%HOFFSET+58]+[%VOFFSET+108] '%H:%M' -fill white -annotate 0x0+[%HOFFSET+60]+[%VOFFSET+110] '%H:%M' -font `fc-match -f '%{file[0]}' '%DATE_FONT_NAME'` -pointsize %DATE_FONT_SIZE -fill '#00000044' -annotate 0x0+[%HOFFSET+58]+[%VOFFSET+58] '%A, %B %d' -fill white -annotate 0x0+[%HOFFSET+60]+[%VOFFSET+60] '%A, %B %d''
INFO: 2019-06-26 05:39:48,526: log_options() 'clock_font = Ubuntu Condensed, 70'
INFO: 2019-06-26 05:39:48,526: log_options() 'configfile = /home/raven/.config/variety/variety.conf'
INFO: 2019-06-26 05:39:48,526: log_options() 'copyto_enabled = False'
INFO: 2019-06-26 05:39:48,526: log_options() 'copyto_folder = Default'
INFO: 2019-06-26 05:39:48,526: log_options() 'desired_color = [160, 160, 160]'
INFO: 2019-06-26 05:39:48,526: log_options() 'desired_color_enabled = False'
INFO: 2019-06-26 05:39:48,526: log_options() 'download_enabled = True'
INFO: 2019-06-26 05:39:48,526: log_options() 'download_folder = /home/raven/.config/variety/Downloaded'
INFO: 2019-06-26 05:39:48,526: log_options() 'download_interval = 600'
INFO: 2019-06-26 05:39:48,526: log_options() 'favorites_folder = /home/raven/.config/variety/Favorites'
INFO: 2019-06-26 05:39:48,527: log_options() 'favorites_operations = [['Downloaded', 'Copy'], ['Fetched', 'Move'], ['Others', 'Copy']]'
INFO: 2019-06-26 05:39:48,527: log_options() 'fetched_folder = /home/raven/.config/variety/Fetched'
INFO: 2019-06-26 05:39:48,527: log_options() 'filters = [[False, 'Keep original', ''], [False, 'Grayscale', '-type Grayscale'], [False, 'Heavy blur', '-blur 120x40'], [False, 'Soft blur', '-blur 20x7'], [False, 'Oil painting', '-paint 8'], [False, 'Pencil sketch', '-colorspace gray \\( +clone -tile ~/.config/variety/pencil_tile.png -draw "color 0,0 reset" +clone +swap -compose color_dodge -composite \\) -fx \'u*.2+v*.8\''], [False, 'Pointilism', '-spread 10 -noise 3'], [False, 'Pixellate', '-scale 3% -scale 3333%']]'
INFO: 2019-06-26 05:39:48,527: log_options() 'icon = Light'
INFO: 2019-06-26 05:39:48,527: log_options() 'lightness_enabled = False'
INFO: 2019-06-26 05:39:48,527: log_options() 'lightness_mode = 0'
INFO: 2019-06-26 05:39:48,527: log_options() 'min_rating = 4'
INFO: 2019-06-26 05:39:48,527: log_options() 'min_rating_enabled = False'
INFO: 2019-06-26 05:39:48,527: log_options() 'min_size = 80'
INFO: 2019-06-26 05:39:48,527: log_options() 'min_size_enabled = False'
INFO: 2019-06-26 05:39:48,527: log_options() 'quota_enabled = True'
INFO: 2019-06-26 05:39:48,527: log_options() 'quota_size = 500'
INFO: 2019-06-26 05:39:48,527: log_options() 'quotes_authors = '
INFO: 2019-06-26 05:39:48,527: log_options() 'quotes_bg_color = [80, 80, 80]'
INFO: 2019-06-26 05:39:48,527: log_options() 'quotes_bg_opacity = 55'
INFO: 2019-06-26 05:39:48,527: log_options() 'quotes_change_enabled = False'
INFO: 2019-06-26 05:39:48,527: log_options() 'quotes_change_interval = 300'
INFO: 2019-06-26 05:39:48,527: log_options() 'quotes_disabled_sources = ['QuotesDaddy']'
INFO: 2019-06-26 05:39:48,527: log_options() 'quotes_enabled = False'
INFO: 2019-06-26 05:39:48,527: log_options() 'quotes_favorites_file = /home/raven/.config/variety/favorite_quotes.txt'
INFO: 2019-06-26 05:39:48,527: log_options() 'quotes_font = Bitstream Charter 30'
INFO: 2019-06-26 05:39:48,527: log_options() 'quotes_hpos = 100'
INFO: 2019-06-26 05:39:48,527: log_options() 'quotes_tags = '
INFO: 2019-06-26 05:39:48,527: log_options() 'quotes_text_color = [255, 255, 255]'
INFO: 2019-06-26 05:39:48,527: log_options() 'quotes_text_shadow = False'
INFO: 2019-06-26 05:39:48,527: log_options() 'quotes_vpos = 40'
INFO: 2019-06-26 05:39:48,527: log_options() 'quotes_width = 70'
INFO: 2019-06-26 05:39:48,527: log_options() 'safe_mode = False'
INFO: 2019-06-26 05:39:48,527: log_options() 'slideshow_custom_enabled = False'
INFO: 2019-06-26 05:39:48,527: log_options() 'slideshow_custom_folder = /home/raven/Billeder'
INFO: 2019-06-26 05:39:48,527: log_options() 'slideshow_downloads_enabled = False'
INFO: 2019-06-26 05:39:48,527: log_options() 'slideshow_fade = 0.4'
INFO: 2019-06-26 05:39:48,527: log_options() 'slideshow_favorites_enabled = True'
INFO: 2019-06-26 05:39:48,527: log_options() 'slideshow_mode = Fullscreen'
INFO: 2019-06-26 05:39:48,527: log_options() 'slideshow_monitor = All'
INFO: 2019-06-26 05:39:48,528: log_options() 'slideshow_pan = 0.05'
INFO: 2019-06-26 05:39:48,528: log_options() 'slideshow_seconds = 6.0'
INFO: 2019-06-26 05:39:48,528: log_options() 'slideshow_sort_order = Random'
INFO: 2019-06-26 05:39:48,528: log_options() 'slideshow_sources_enabled = True'
INFO: 2019-06-26 05:39:48,528: log_options() 'slideshow_zoom = 0.2'
INFO: 2019-06-26 05:39:48,528: log_options() 'smart_enabled = False'
INFO: 2019-06-26 05:39:48,528: log_options() 'smart_notice_shown = False'
INFO: 2019-06-26 05:39:48,528: log_options() 'smart_register_shown = False'
INFO: 2019-06-26 05:39:48,528: log_options() 'sources = [[True, 3, 'The Favorites folder'], [True, 4, 'The Fetched folder'], [True, 2, '/usr/share/backgrounds'], [True, 6, 'Random wallpapers from Desktoppr.co'], [True, 15, 'Bing Photo of the Day'], [True, 16, 'High-resolution photos from Unsplash.com'], [True, 8, "NASA's Astronomy Picture of the Day"], [False, 11, 'World Sunlight Map - live wallpaper from Die.net'], [True, 7, 'user:www.flickr.com/photos/peter-levi/;user_id:93647178@N00;']]'
INFO: 2019-06-26 05:39:48,528: log_options() 'stats_enabled = True'
INFO: 2019-06-26 05:39:48,528: log_options() 'stats_notice_shown = False'
INFO: 2019-06-26 05:39:48,528: log_options() 'sync_enabled = True'
INFO: 2019-06-26 05:39:48,528: log_options() 'use_landscape_enabled = True'
INFO: 2019-06-26 05:39:48,528: reload_config() 'No need to clear prepared queue'
INFO: 2019-06-26 05:39:48,528: load_last_change_time() 'Change interval < 6 hours, ignore persisted last_change_time, wait initially the whole interval: 300'
INFO: 2019-06-26 05:39:48,528: update_indicator() 'Setting file info to: /home/raven/.config/variety/Downloaded/Desktoppr/0336_2560_1600.jpg'
INFO: 2019-06-26 05:39:48,531: regular_change_thread() 'regular_change thread running'
INFO: 2019-06-26 05:39:48,531: regular_change_thread() 'regular_change: waiting till user resumes'
INFO: 2019-06-26 05:39:48,531: prepare_thread() 'Prepare thread running'
INFO: 2019-06-26 05:39:48,531: prepare_thread() 'Prepared buffer contains 0 images'
INFO: 2019-06-26 05:39:48,532: prepare_thread() 'Preparing some images'
INFO: 2019-06-26 05:39:48,533: update_indicator_icon() 'Creating indicator'
WARNING: 2019-06-26 05:39:48,544: create_menu() 'Variety Slideshow is not installed. This is an optional extension adding pan-and-zoom slideshows to Variety: see https://github.com/peterlevi/variety-slideshow for details'
INFO: 2019-06-26 05:39:48,546: create_indicator() 'indicator backend: AppIndicator3'
INFO: 2019-06-26 05:39:48,565: set_from_theme_icon() 'Showing indicator icon variety-indicator from GTK theme'
INFO: 2019-06-26 05:39:48,566: update_indicator() 'Setting file info to: /home/raven/.config/variety/Downloaded/Desktoppr/0336_2560_1600.jpg'
INFO: 2019-06-26 05:39:48,626: prepare_thread() 'After search prepared buffer contains 98 images'
INFO: 2019-06-26 05:39:48,629: do_set_wp() 'Calling do_set_wp with /home/raven/.config/variety/Downloaded/Desktoppr/0336_2560_1600.jpg, time: 1561520388.6290894'
INFO: 2019-06-26 05:39:48,642: update_indicator() 'Setting file info to: /home/raven/.config/variety/Downloaded/Desktoppr/0336_2560_1600.jpg'
INFO: 2019-06-26 05:39:49,956: reload() 'Reloading preferences dialog'
INFO: 2019-06-26 05:40:08,550: server_options_thread() 'Fetching server options from http://tiny.cc/variety-options-063'
ERROR: 2019-06-26 05:40:33,077: server_options_thread() 'Could not fetch Variety serverside options'
Traceback (most recent call last):
  File "/usr/lib/python3.7/site-packages/variety/VarietyWindow.py", line 939, in server_options_thread
    self.server_options = Util.fetch_json(VarietyWindow.SERVERSIDE_OPTIONS_URL)
  File "/usr/lib/python3.7/site-packages/variety/Util.py", line 593, in fetch_json
    return Util.request(url, data).json()
  File "/usr/lib/python3.7/site-packages/requests/models.py", line 897, in json
    return complexjson.loads(self.text, **kwargs)
  File "/usr/lib/python3.7/json/__init__.py", line 348, in loads
    return _default_decoder.decode(s)
  File "/usr/lib/python3.7/json/decoder.py", line 337, in decode
    obj, end = self.raw_decode(s, idx=_w(s, 0).end())
  File "/usr/lib/python3.7/json/decoder.py", line 355, in raw_decode
    raise JSONDecodeError("Expecting value", s, err.value) from None
json.decoder.JSONDecodeError: Expecting value: line 1 column 1 (char 0)
INFO: 2019-06-26 05:41:03,102: server_options_thread() 'Fetching server options from http://tiny.cc/variety-options-063'
ERROR: 2019-06-26 05:41:18,120: server_options_thread() 'Could not fetch Variety serverside options'
Traceback (most recent call last):
  File "/usr/lib/python3.7/site-packages/urllib3/connection.py", line 160, in _new_conn
    (self._dns_host, self.port), self.timeout, **extra_kw)
  File "/usr/lib/python3.7/site-packages/urllib3/util/connection.py", line 80, in create_connection
    raise err
  File "/usr/lib/python3.7/site-packages/urllib3/util/connection.py", line 70, in create_connection
    sock.connect(sa)
socket.timeout: timed out

During handling of the above exception, another exception occurred:

Traceback (most recent call last):
  File "/usr/lib/python3.7/site-packages/urllib3/connectionpool.py", line 603, in urlopen
    chunked=chunked)
  File "/usr/lib/python3.7/site-packages/urllib3/connectionpool.py", line 355, in _make_request
    conn.request(method, url, **httplib_request_kw)
  File "/usr/lib/python3.7/http/client.py", line 1229, in request
    self._send_request(method, url, body, headers, encode_chunked)
  File "/usr/lib/python3.7/http/client.py", line 1275, in _send_request
    self.endheaders(body, encode_chunked=encode_chunked)
  File "/usr/lib/python3.7/http/client.py", line 1224, in endheaders
    self._send_output(message_body, encode_chunked=encode_chunked)
  File "/usr/lib/python3.7/http/client.py", line 1016, in _send_output
    self.send(msg)
  File "/usr/lib/python3.7/http/client.py", line 956, in send
    self.connect()
  File "/usr/lib/python3.7/site-packages/urllib3/connection.py", line 183, in connect
    conn = self._new_conn()
  File "/usr/lib/python3.7/site-packages/urllib3/connection.py", line 165, in _new_conn
    (self.host, self.timeout))
urllib3.exceptions.ConnectTimeoutError: (<urllib3.connection.HTTPConnection object at 0x7f26581cb5f8>, 'Connection to tiny.cc timed out. (connect timeout=5)')

During handling of the above exception, another exception occurred:

Traceback (most recent call last):
  File "/usr/lib/python3.7/site-packages/requests/adapters.py", line 449, in send
    timeout=timeout
  File "/usr/lib/python3.7/site-packages/urllib3/connectionpool.py", line 641, in urlopen
    _stacktrace=sys.exc_info()[2])
  File "/usr/lib/python3.7/site-packages/urllib3/util/retry.py", line 399, in increment
    raise MaxRetryError(_pool, url, error or ResponseError(cause))
urllib3.exceptions.MaxRetryError: HTTPConnectionPool(host='tiny.cc', port=80): Max retries exceeded with url: /variety-options-063 (Caused by ConnectTimeoutError(<urllib3.connection.HTTPConnection object at 0x7f26581cb5f8>, 'Connection to tiny.cc timed out. (connect timeout=5)'))

During handling of the above exception, another exception occurred:

Traceback (most recent call last):
  File "/usr/lib/python3.7/site-packages/variety/VarietyWindow.py", line 939, in server_options_thread
    self.server_options = Util.fetch_json(VarietyWindow.SERVERSIDE_OPTIONS_URL)
  File "/usr/lib/python3.7/site-packages/variety/Util.py", line 593, in fetch_json
    return Util.request(url, data).json()
  File "/usr/lib/python3.7/site-packages/variety/Util.py", line 571, in request
    timeout=timeout)
  File "/usr/lib/python3.7/site-packages/requests/api.py", line 60, in request
    return session.request(method=method, url=url, **kwargs)
  File "/usr/lib/python3.7/site-packages/requests/sessions.py", line 533, in request
    resp = self.send(prep, **send_kwargs)
  File "/usr/lib/python3.7/site-packages/requests/sessions.py", line 646, in send
    r = adapter.send(request, **kwargs)
  File "/usr/lib/python3.7/site-packages/requests/adapters.py", line 504, in send
    raise ConnectTimeout(e, request=request)
requests.exceptions.ConnectTimeout: HTTPConnectionPool(host='tiny.cc', port=80): Max retries exceeded with url: /variety-options-063 (Caused by ConnectTimeoutError(<urllib3.connection.HTTPConnection object at 0x7f26581cb5f8>, 'Connection to tiny.cc timed out. (connect timeout=5)'))
INFO: 2019-06-26 05:41:48,153: server_options_thread() 'Fetching server options from http://tiny.cc/variety-options-063'
ERROR: 2019-06-26 05:41:48,172: server_options_thread() 'Could not fetch Variety serverside options'
Traceback (most recent call last):
  File "/usr/lib/python3.7/site-packages/urllib3/connection.py", line 160, in _new_conn
    (self._dns_host, self.port), self.timeout, **extra_kw)
  File "/usr/lib/python3.7/site-packages/urllib3/util/connection.py", line 57, in create_connection
    for res in socket.getaddrinfo(host, port, family, socket.SOCK_STREAM):
  File "/usr/lib/python3.7/socket.py", line 748, in getaddrinfo
    for res in _socket.getaddrinfo(host, port, family, type, proto, flags):
socket.gaierror: [Errno -2] Navn eller tjeneste ukendt

During handling of the above exception, another exception occurred:

Traceback (most recent call last):
  File "/usr/lib/python3.7/site-packages/urllib3/connectionpool.py", line 603, in urlopen
    chunked=chunked)
  File "/usr/lib/python3.7/site-packages/urllib3/connectionpool.py", line 355, in _make_request
    conn.request(method, url, **httplib_request_kw)
  File "/usr/lib/python3.7/http/client.py", line 1229, in request
    self._send_request(method, url, body, headers, encode_chunked)
  File "/usr/lib/python3.7/http/client.py", line 1275, in _send_request
    self.endheaders(body, encode_chunked=encode_chunked)
  File "/usr/lib/python3.7/http/client.py", line 1224, in endheaders
    self._send_output(message_body, encode_chunked=encode_chunked)
  File "/usr/lib/python3.7/http/client.py", line 1016, in _send_output
    self.send(msg)
  File "/usr/lib/python3.7/http/client.py", line 956, in send
    self.connect()
  File "/usr/lib/python3.7/site-packages/urllib3/connection.py", line 183, in connect
    conn = self._new_conn()
  File "/usr/lib/python3.7/site-packages/urllib3/connection.py", line 169, in _new_conn
    self, "Failed to establish a new connection: %s" % e)
urllib3.exceptions.NewConnectionError: <urllib3.connection.HTTPConnection object at 0x7f26581cbd30>: Failed to establish a new connection: [Errno -2] Navn eller tjeneste ukendt

During handling of the above exception, another exception occurred:

Traceback (most recent call last):
  File "/usr/lib/python3.7/site-packages/requests/adapters.py", line 449, in send
    timeout=timeout
  File "/usr/lib/python3.7/site-packages/urllib3/connectionpool.py", line 641, in urlopen
    _stacktrace=sys.exc_info()[2])
  File "/usr/lib/python3.7/site-packages/urllib3/util/retry.py", line 399, in increment
    raise MaxRetryError(_pool, url, error or ResponseError(cause))
urllib3.exceptions.MaxRetryError: HTTPConnectionPool(host='tiny.cc', port=80): Max retries exceeded with url: /variety-options-063 (Caused by NewConnectionError('<urllib3.connection.HTTPConnection object at 0x7f26581cbd30>: Failed to establish a new connection: [Errno -2] Navn eller tjeneste ukendt'))

During handling of the above exception, another exception occurred:

Traceback (most recent call last):
  File "/usr/lib/python3.7/site-packages/variety/VarietyWindow.py", line 939, in server_options_thread
    self.server_options = Util.fetch_json(VarietyWindow.SERVERSIDE_OPTIONS_URL)
  File "/usr/lib/python3.7/site-packages/variety/Util.py", line 593, in fetch_json
    return Util.request(url, data).json()
  File "/usr/lib/python3.7/site-packages/variety/Util.py", line 571, in request
    timeout=timeout)
  File "/usr/lib/python3.7/site-packages/requests/api.py", line 60, in request
    return session.request(method=method, url=url, **kwargs)
  File "/usr/lib/python3.7/site-packages/requests/sessions.py", line 533, in request
    resp = self.send(prep, **send_kwargs)
  File "/usr/lib/python3.7/site-packages/requests/sessions.py", line 646, in send
    r = adapter.send(request, **kwargs)
  File "/usr/lib/python3.7/site-packages/requests/adapters.py", line 516, in send
    raise ConnectionError(e, request=request)
requests.exceptions.ConnectionError: HTTPConnectionPool(host='tiny.cc', port=80): Max retries exceeded with url: /variety-options-063 (Caused by NewConnectionError('<urllib3.connection.HTTPConnection object at 0x7f26581cbd30>: Failed to establish a new connection: [Errno -2] Navn eller tjeneste ukendt'))
INFO: 2019-06-26 05:42:18,204: server_options_thread() 'Fetching server options from http://tiny.cc/variety-options-063'
ERROR: 2019-06-26 05:42:28,216: server_options_thread() 'Could not fetch Variety serverside options'
Traceback (most recent call last):
  File "/usr/lib/python3.7/site-packages/urllib3/connection.py", line 160, in _new_conn
    (self._dns_host, self.port), self.timeout, **extra_kw)
  File "/usr/lib/python3.7/site-packages/urllib3/util/connection.py", line 80, in create_connection
    raise err
  File "/usr/lib/python3.7/site-packages/urllib3/util/connection.py", line 70, in create_connection
    sock.connect(sa)
socket.timeout: timed out

During handling of the above exception, another exception occurred:

Traceback (most recent call last):
  File "/usr/lib/python3.7/site-packages/urllib3/connectionpool.py", line 603, in urlopen
    chunked=chunked)
  File "/usr/lib/python3.7/site-packages/urllib3/connectionpool.py", line 355, in _make_request
    conn.request(method, url, **httplib_request_kw)
  File "/usr/lib/python3.7/http/client.py", line 1229, in request
    self._send_request(method, url, body, headers, encode_chunked)
  File "/usr/lib/python3.7/http/client.py", line 1275, in _send_request
    self.endheaders(body, encode_chunked=encode_chunked)
  File "/usr/lib/python3.7/http/client.py", line 1224, in endheaders
    self._send_output(message_body, encode_chunked=encode_chunked)
  File "/usr/lib/python3.7/http/client.py", line 1016, in _send_output
    self.send(msg)
  File "/usr/lib/python3.7/http/client.py", line 956, in send
    self.connect()
  File "/usr/lib/python3.7/site-packages/urllib3/connection.py", line 183, in connect
    conn = self._new_conn()
  File "/usr/lib/python3.7/site-packages/urllib3/connection.py", line 165, in _new_conn
    (self.host, self.timeout))
urllib3.exceptions.ConnectTimeoutError: (<urllib3.connection.HTTPConnection object at 0x7f26581c9358>, 'Connection to tiny.cc timed out. (connect timeout=5)')

During handling of the above exception, another exception occurred:

Traceback (most recent call last):
  File "/usr/lib/python3.7/site-packages/requests/adapters.py", line 449, in send
    timeout=timeout
  File "/usr/lib/python3.7/site-packages/urllib3/connectionpool.py", line 641, in urlopen
    _stacktrace=sys.exc_info()[2])
  File "/usr/lib/python3.7/site-packages/urllib3/util/retry.py", line 399, in increment
    raise MaxRetryError(_pool, url, error or ResponseError(cause))
urllib3.exceptions.MaxRetryError: HTTPConnectionPool(host='tiny.cc', port=80): Max retries exceeded with url: /variety-options-063 (Caused by ConnectTimeoutError(<urllib3.connection.HTTPConnection object at 0x7f26581c9358>, 'Connection to tiny.cc timed out. (connect timeout=5)'))

During handling of the above exception, another exception occurred:

Traceback (most recent call last):
  File "/usr/lib/python3.7/site-packages/variety/VarietyWindow.py", line 939, in server_options_thread
    self.server_options = Util.fetch_json(VarietyWindow.SERVERSIDE_OPTIONS_URL)
  File "/usr/lib/python3.7/site-packages/variety/Util.py", line 593, in fetch_json
    return Util.request(url, data).json()
  File "/usr/lib/python3.7/site-packages/variety/Util.py", line 571, in request
    timeout=timeout)
  File "/usr/lib/python3.7/site-packages/requests/api.py", line 60, in request
    return session.request(method=method, url=url, **kwargs)
  File "/usr/lib/python3.7/site-packages/requests/sessions.py", line 533, in request
    resp = self.send(prep, **send_kwargs)
  File "/usr/lib/python3.7/site-packages/requests/sessions.py", line 646, in send
    r = adapter.send(request, **kwargs)
  File "/usr/lib/python3.7/site-packages/requests/adapters.py", line 504, in send
    raise ConnectTimeout(e, request=request)
requests.exceptions.ConnectTimeout: HTTPConnectionPool(host='tiny.cc', port=80): Max retries exceeded with url: /variety-options-063 (Caused by ConnectTimeoutError(<urllib3.connection.HTTPConnection object at 0x7f26581c9358>, 'Connection to tiny.cc timed out. (connect timeout=5)'))
INFO: 2019-06-26 05:42:58,248: server_options_thread() 'Fetching server options from http://tiny.cc/variety-options-063'
ERROR: 2019-06-26 05:42:58,254: server_options_thread() 'Could not fetch Variety serverside options'
Traceback (most recent call last):
  File "/usr/lib/python3.7/site-packages/urllib3/connection.py", line 160, in _new_conn
    (self._dns_host, self.port), self.timeout, **extra_kw)
  File "/usr/lib/python3.7/site-packages/urllib3/util/connection.py", line 57, in create_connection
    for res in socket.getaddrinfo(host, port, family, socket.SOCK_STREAM):
  File "/usr/lib/python3.7/socket.py", line 748, in getaddrinfo
    for res in _socket.getaddrinfo(host, port, family, type, proto, flags):
socket.gaierror: [Errno -2] Navn eller tjeneste ukendt

During handling of the above exception, another exception occurred:

Traceback (most recent call last):
  File "/usr/lib/python3.7/site-packages/urllib3/connectionpool.py", line 603, in urlopen
    chunked=chunked)
  File "/usr/lib/python3.7/site-packages/urllib3/connectionpool.py", line 355, in _make_request
    conn.request(method, url, **httplib_request_kw)
  File "/usr/lib/python3.7/http/client.py", line 1229, in request
    self._send_request(method, url, body, headers, encode_chunked)
  File "/usr/lib/python3.7/http/client.py", line 1275, in _send_request
    self.endheaders(body, encode_chunked=encode_chunked)
  File "/usr/lib/python3.7/http/client.py", line 1224, in endheaders
    self._send_output(message_body, encode_chunked=encode_chunked)
  File "/usr/lib/python3.7/http/client.py", line 1016, in _send_output
    self.send(msg)
  File "/usr/lib/python3.7/http/client.py", line 956, in send
    self.connect()
  File "/usr/lib/python3.7/site-packages/urllib3/connection.py", line 183, in connect
    conn = self._new_conn()
  File "/usr/lib/python3.7/site-packages/urllib3/connection.py", line 169, in _new_conn
    self, "Failed to establish a new connection: %s" % e)
urllib3.exceptions.NewConnectionError: <urllib3.connection.HTTPConnection object at 0x7f26581cb2b0>: Failed to establish a new connection: [Errno -2] Navn eller tjeneste ukendt

During handling of the above exception, another exception occurred:

Traceback (most recent call last):
  File "/usr/lib/python3.7/site-packages/requests/adapters.py", line 449, in send
    timeout=timeout
  File "/usr/lib/python3.7/site-packages/urllib3/connectionpool.py", line 641, in urlopen
    _stacktrace=sys.exc_info()[2])
  File "/usr/lib/python3.7/site-packages/urllib3/util/retry.py", line 399, in increment
    raise MaxRetryError(_pool, url, error or ResponseError(cause))
urllib3.exceptions.MaxRetryError: HTTPConnectionPool(host='tiny.cc', port=80): Max retries exceeded with url: /variety-options-063 (Caused by NewConnectionError('<urllib3.connection.HTTPConnection object at 0x7f26581cb2b0>: Failed to establish a new connection: [Errno -2] Navn eller tjeneste ukendt'))

During handling of the above exception, another exception occurred:

Traceback (most recent call last):
  File "/usr/lib/python3.7/site-packages/variety/VarietyWindow.py", line 939, in server_options_thread
    self.server_options = Util.fetch_json(VarietyWindow.SERVERSIDE_OPTIONS_URL)
  File "/usr/lib/python3.7/site-packages/variety/Util.py", line 593, in fetch_json
    return Util.request(url, data).json()
  File "/usr/lib/python3.7/site-packages/variety/Util.py", line 571, in request
    timeout=timeout)
  File "/usr/lib/python3.7/site-packages/requests/api.py", line 60, in request
    return session.request(method=method, url=url, **kwargs)
  File "/usr/lib/python3.7/site-packages/requests/sessions.py", line 533, in request
    resp = self.send(prep, **send_kwargs)
  File "/usr/lib/python3.7/site-packages/requests/sessions.py", line 646, in send
    r = adapter.send(request, **kwargs)
  File "/usr/lib/python3.7/site-packages/requests/adapters.py", line 516, in send
    raise ConnectionError(e, request=request)
requests.exceptions.ConnectionError: HTTPConnectionPool(host='tiny.cc', port=80): Max retries exceeded with url: /variety-options-063 (Caused by NewConnectionError('<urllib3.connection.HTTPConnection object at 0x7f26581cb2b0>: Failed to establish a new connection: [Errno -2] Navn eller tjeneste ukendt'))
INFO: 2019-06-26 05:49:48,539: purge_downloaded() 'Refreshed download folder size: 368 mb'
INFO: 2019-06-26 05:49:48,540: parse_server_options() 'Flickr: parsing serverside options'
ERROR: 2019-06-26 05:49:48,540: parse_server_options() 'Could not parse Flickr serverside options, using defaults 60, 600'
Traceback (most recent call last):
  File "/usr/lib/python3.7/site-packages/variety/Downloader.py", line 143, in parse_server_options
    options = self.parent.server_options[key]
KeyError: 'flickr'
INFO: 2019-06-26 05:49:48,541: download_one() 'Downloading an image from Flickr, user:www.flickr.com/photos/peter-levi/;user_id:93647178@N00;'
INFO: 2019-06-26 05:49:48,541: download_one() 'Queue size: 0'
INFO: 2019-06-26 05:49:48,541: fill_queue() 'Filling Flickr download queue: user:www.flickr.com/photos/peter-levi/;user_id:93647178@N00;'
INFO: 2019-06-26 05:49:48,541: fetch() 'Making flickr API call: https://api.flickr.com/services/rest/?method=flickr.photos.search&api_key=0553a848c09bcfd21d3a984d9408c04e&per_page=500&tag_mode=all&format=json&nojsoncallback=1&user_id=93647178@N00'
INFO: 2019-06-26 05:49:51,503: fill_queue() '1 pages in the search results, using page 1'
INFO: 2019-06-26 05:49:51,504: fetch() 'Making flickr API call: https://api.flickr.com/services/rest/?method=flickr.photos.search&api_key=0553a848c09bcfd21d3a984d9408c04e&per_page=500&tag_mode=all&format=json&nojsoncallback=1&user_id=93647178@N00&extras=owner_name,description,tags,o_dims,url_o,url_k,url_h,url_l&page=1'
INFO: 2019-06-26 05:49:53,958: process_photos_in_response() 'Queue size is 0, populating with images for size suffix o'
INFO: 2019-06-26 05:49:53,962: fill_queue() 'Flickr queue populated with 53 URLs'
INFO: 2019-06-26 05:49:53,962: download_one() 'Photo URL: https://www.flickr.com/photos/93647178@N00/7527884030'
INFO: 2019-06-26 05:49:53,962: save_locally() 'Origin URL: https://www.flickr.com/photos/93647178@N00/7527884030'
INFO: 2019-06-26 05:49:53,962: save_locally() 'Image URL: https://live.staticflickr.com/8429/7527884030_003230e977_o.jpg'
INFO: 2019-06-26 05:49:53,962: save_locally() 'Local name: /home/raven/.config/variety/Downloaded/flickr_user_www_flickr_com_photos_peter_levi__user_id_93647178_N00_/7527884030_003230e977_o.jpg'
INFO: 2019-06-26 05:49:55,804: save_locally() 'Download complete'
INFO: 2019-06-26 05:49:55,805: update_indicator() 'Setting file info to: /home/raven/.config/variety/Downloaded/Desktoppr/0336_2560_1600.jpg'
INFO: 2019-06-26 05:49:55,806: download_one_from() 'Adding downloaded file /home/raven/.config/variety/Downloaded/flickr_user_www_flickr_com_photos_peter_levi__user_id_93647178_N00_/7527884030_003230e977_o.jpg to prepared_from_downloads queue'
INFO: 2019-06-26 05:59:48,536: purge_downloaded() 'Refreshed download folder size: 369 mb'
INFO: 2019-06-26 05:59:48,536: download_one() 'Downloading an image from NASA's Astro Pic of the Day, nasa_apod'
INFO: 2019-06-26 05:59:48,536: download_one() 'Queue size: 0'
INFO: 2019-06-26 05:59:48,536: fill_queue() 'Filling APOD queue from Archive'
ERROR: 2019-06-26 05:59:48,542: download_thread() 'Could not download wallpaper:'
Traceback (most recent call last):
  File "/usr/lib/python3.7/site-packages/urllib3/connection.py", line 160, in _new_conn
    (self._dns_host, self.port), self.timeout, **extra_kw)
  File "/usr/lib/python3.7/site-packages/urllib3/util/connection.py", line 57, in create_connection
    for res in socket.getaddrinfo(host, port, family, socket.SOCK_STREAM):
  File "/usr/lib/python3.7/socket.py", line 748, in getaddrinfo
    for res in _socket.getaddrinfo(host, port, family, type, proto, flags):
socket.gaierror: [Errno -2] Navn eller tjeneste ukendt

During handling of the above exception, another exception occurred:

Traceback (most recent call last):
  File "/usr/lib/python3.7/site-packages/urllib3/connectionpool.py", line 603, in urlopen
    chunked=chunked)
  File "/usr/lib/python3.7/site-packages/urllib3/connectionpool.py", line 355, in _make_request
    conn.request(method, url, **httplib_request_kw)
  File "/usr/lib/python3.7/http/client.py", line 1229, in request
    self._send_request(method, url, body, headers, encode_chunked)
  File "/usr/lib/python3.7/http/client.py", line 1275, in _send_request
    self.endheaders(body, encode_chunked=encode_chunked)
  File "/usr/lib/python3.7/http/client.py", line 1224, in endheaders
    self._send_output(message_body, encode_chunked=encode_chunked)
  File "/usr/lib/python3.7/http/client.py", line 1016, in _send_output
    self.send(msg)
  File "/usr/lib/python3.7/http/client.py", line 956, in send
    self.connect()
  File "/usr/lib/python3.7/site-packages/urllib3/connection.py", line 183, in connect
    conn = self._new_conn()
  File "/usr/lib/python3.7/site-packages/urllib3/connection.py", line 169, in _new_conn
    self, "Failed to establish a new connection: %s" % e)
urllib3.exceptions.NewConnectionError: <urllib3.connection.HTTPConnection object at 0x7f26581bad30>: Failed to establish a new connection: [Errno -2] Navn eller tjeneste ukendt

During handling of the above exception, another exception occurred:

Traceback (most recent call last):
  File "/usr/lib/python3.7/site-packages/requests/adapters.py", line 449, in send
    timeout=timeout
  File "/usr/lib/python3.7/site-packages/urllib3/connectionpool.py", line 641, in urlopen
    _stacktrace=sys.exc_info()[2])
  File "/usr/lib/python3.7/site-packages/urllib3/util/retry.py", line 399, in increment
    raise MaxRetryError(_pool, url, error or ResponseError(cause))
urllib3.exceptions.MaxRetryError: HTTPConnectionPool(host='apod.nasa.gov', port=80): Max retries exceeded with url: /apod/archivepix.html (Caused by NewConnectionError('<urllib3.connection.HTTPConnection object at 0x7f26581bad30>: Failed to establish a new connection: [Errno -2] Navn eller tjeneste ukendt'))

During handling of the above exception, another exception occurred:

Traceback (most recent call last):
  File "/usr/lib/python3.7/site-packages/variety/VarietyWindow.py", line 986, in download_thread
    self.download_one_from(downloader)
  File "/usr/lib/python3.7/site-packages/variety/VarietyWindow.py", line 1018, in download_one_from
    file = downloader.download_one()
  File "/usr/lib/python3.7/site-packages/variety/APODDownloader.py", line 41, in download_one
    self.fill_queue()
  File "/usr/lib/python3.7/site-packages/variety/APODDownloader.py", line 68, in fill_queue
    s = self.fetch("http://apod.nasa.gov/apod/archivepix.html")
  File "/usr/lib/python3.7/site-packages/variety/APODDownloader.py", line 34, in fetch
    return Util.xml_soup(url) if xml else Util.html_soup(url)
  File "/usr/lib/python3.7/site-packages/variety/Util.py", line 597, in html_soup
    return bs4.BeautifulSoup(Util.fetch(url, data), "lxml")
  File "/usr/lib/python3.7/site-packages/variety/Util.py", line 585, in fetch
    return Util.request(url, data).text
  File "/usr/lib/python3.7/site-packages/variety/Util.py", line 571, in request
    timeout=timeout)
  File "/usr/lib/python3.7/site-packages/requests/api.py", line 60, in request
    return session.request(method=method, url=url, **kwargs)
  File "/usr/lib/python3.7/site-packages/requests/sessions.py", line 533, in request
    resp = self.send(prep, **send_kwargs)
  File "/usr/lib/python3.7/site-packages/requests/sessions.py", line 646, in send
    r = adapter.send(request, **kwargs)
  File "/usr/lib/python3.7/site-packages/requests/adapters.py", line 516, in send
    raise ConnectionError(e, request=request)
requests.exceptions.ConnectionError: HTTPConnectionPool(host='apod.nasa.gov', port=80): Max retries exceeded with url: /apod/archivepix.html (Caused by NewConnectionError('<urllib3.connection.HTTPConnection object at 0x7f26581bad30>: Failed to establish a new connection: [Errno -2] Navn eller tjeneste ukendt'))
INFO: 2019-06-26 06:09:48,532: parse_server_options() 'Flickr: parsing serverside options'
ERROR: 2019-06-26 06:09:48,533: parse_server_options() 'Could not parse Flickr serverside options, using defaults 60, 600'
Traceback (most recent call last):
  File "/usr/lib/python3.7/site-packages/variety/Downloader.py", line 143, in parse_server_options
    options = self.parent.server_options[key]
KeyError: 'flickr'
INFO: 2019-06-26 06:09:48,533: download_one() 'Downloading an image from Flickr, user:www.flickr.com/photos/peter-levi/;user_id:93647178@N00;'
INFO: 2019-06-26 06:09:48,533: download_one() 'Queue size: 52'
INFO: 2019-06-26 06:09:48,533: download_one() 'Photo URL: https://www.flickr.com/photos/93647178@N00/7527959832'
INFO: 2019-06-26 06:09:48,534: save_locally() 'Origin URL: https://www.flickr.com/photos/93647178@N00/7527959832'
INFO: 2019-06-26 06:09:48,534: save_locally() 'Image URL: https://live.staticflickr.com/7267/7527959832_fbb4d21ff9_o.jpg'
INFO: 2019-06-26 06:09:48,534: save_locally() 'Local name: /home/raven/.config/variety/Downloaded/flickr_user_www_flickr_com_photos_peter_levi__user_id_93647178_N00_/7527959832_fbb4d21ff9_o.jpg'
INFO: 2019-06-26 06:09:55,810: save_locally() 'Download complete'
INFO: 2019-06-26 06:09:55,811: update_indicator() 'Setting file info to: /home/raven/.config/variety/Downloaded/Desktoppr/0336_2560_1600.jpg'
INFO: 2019-06-26 06:09:55,816: download_one_from() 'Adding downloaded file /home/raven/.config/variety/Downloaded/flickr_user_www_flickr_com_photos_peter_levi__user_id_93647178_N00_/7527959832_fbb4d21ff9_o.jpg to prepared_from_downloads queue'
INFO: 2019-06-26 06:19:48,533: download_one() 'Downloading an image from NASA's Astro Pic of the Day, nasa_apod'
INFO: 2019-06-26 06:19:48,533: download_one() 'Queue size: 0'
INFO: 2019-06-26 06:19:48,533: fill_queue() 'Filling APOD queue from Archive'
ERROR: 2019-06-26 06:19:55,037: download_thread() 'Could not download wallpaper:'
Traceback (most recent call last):
  File "/usr/lib/python3.7/site-packages/urllib3/connectionpool.py", line 603, in urlopen
    chunked=chunked)
  File "/usr/lib/python3.7/site-packages/urllib3/connectionpool.py", line 387, in _make_request
    six.raise_from(e, None)
  File "<string>", line 2, in raise_from
  File "/usr/lib/python3.7/site-packages/urllib3/connectionpool.py", line 383, in _make_request
    httplib_response = conn.getresponse()
  File "/usr/lib/python3.7/http/client.py", line 1321, in getresponse
    response.begin()
  File "/usr/lib/python3.7/http/client.py", line 296, in begin
    version, status, reason = self._read_status()
  File "/usr/lib/python3.7/http/client.py", line 257, in _read_status
    line = str(self.fp.readline(_MAXLINE + 1), "iso-8859-1")
  File "/usr/lib/python3.7/socket.py", line 589, in readinto
    return self._sock.recv_into(b)
  File "/usr/lib/python3.7/ssl.py", line 1052, in recv_into
    return self.read(nbytes, buffer)
  File "/usr/lib/python3.7/ssl.py", line 911, in read
    return self._sslobj.read(len, buffer)
ConnectionResetError: [Errno 104] Forbindelsen brudt i den anden ende

During handling of the above exception, another exception occurred:

Traceback (most recent call last):
  File "/usr/lib/python3.7/site-packages/requests/adapters.py", line 449, in send
    timeout=timeout
  File "/usr/lib/python3.7/site-packages/urllib3/connectionpool.py", line 641, in urlopen
    _stacktrace=sys.exc_info()[2])
  File "/usr/lib/python3.7/site-packages/urllib3/util/retry.py", line 368, in increment
    raise six.reraise(type(error), error, _stacktrace)
  File "/usr/lib/python3.7/site-packages/urllib3/packages/six.py", line 685, in reraise
    raise value.with_traceback(tb)
  File "/usr/lib/python3.7/site-packages/urllib3/connectionpool.py", line 603, in urlopen
    chunked=chunked)
  File "/usr/lib/python3.7/site-packages/urllib3/connectionpool.py", line 387, in _make_request
    six.raise_from(e, None)
  File "<string>", line 2, in raise_from
  File "/usr/lib/python3.7/site-packages/urllib3/connectionpool.py", line 383, in _make_request
    httplib_response = conn.getresponse()
  File "/usr/lib/python3.7/http/client.py", line 1321, in getresponse
    response.begin()
  File "/usr/lib/python3.7/http/client.py", line 296, in begin
    version, status, reason = self._read_status()
  File "/usr/lib/python3.7/http/client.py", line 257, in _read_status
    line = str(self.fp.readline(_MAXLINE + 1), "iso-8859-1")
  File "/usr/lib/python3.7/socket.py", line 589, in readinto
    return self._sock.recv_into(b)
  File "/usr/lib/python3.7/ssl.py", line 1052, in recv_into
    return self.read(nbytes, buffer)
  File "/usr/lib/python3.7/ssl.py", line 911, in read
    return self._sslobj.read(len, buffer)
urllib3.exceptions.ProtocolError: ('Connection aborted.', ConnectionResetError(104, 'Forbindelsen brudt i den anden ende'))

During handling of the above exception, another exception occurred:

Traceback (most recent call last):
  File "/usr/lib/python3.7/site-packages/variety/VarietyWindow.py", line 986, in download_thread
    self.download_one_from(downloader)
  File "/usr/lib/python3.7/site-packages/variety/VarietyWindow.py", line 1018, in download_one_from
    file = downloader.download_one()
  File "/usr/lib/python3.7/site-packages/variety/APODDownloader.py", line 41, in download_one
    self.fill_queue()
  File "/usr/lib/python3.7/site-packages/variety/APODDownloader.py", line 68, in fill_queue
    s = self.fetch("http://apod.nasa.gov/apod/archivepix.html")
  File "/usr/lib/python3.7/site-packages/variety/APODDownloader.py", line 34, in fetch
    return Util.xml_soup(url) if xml else Util.html_soup(url)
  File "/usr/lib/python3.7/site-packages/variety/Util.py", line 597, in html_soup
    return bs4.BeautifulSoup(Util.fetch(url, data), "lxml")
  File "/usr/lib/python3.7/site-packages/variety/Util.py", line 585, in fetch
    return Util.request(url, data).text
  File "/usr/lib/python3.7/site-packages/variety/Util.py", line 571, in request
    timeout=timeout)
  File "/usr/lib/python3.7/site-packages/requests/api.py", line 60, in request
    return session.request(method=method, url=url, **kwargs)
  File "/usr/lib/python3.7/site-packages/requests/sessions.py", line 533, in request
    resp = self.send(prep, **send_kwargs)
  File "/usr/lib/python3.7/site-packages/requests/sessions.py", line 668, in send
    history = [resp for resp in gen] if allow_redirects else []
  File "/usr/lib/python3.7/site-packages/requests/sessions.py", line 668, in <listcomp>
    history = [resp for resp in gen] if allow_redirects else []
  File "/usr/lib/python3.7/site-packages/requests/sessions.py", line 247, in resolve_redirects
    **adapter_kwargs
  File "/usr/lib/python3.7/site-packages/requests/sessions.py", line 646, in send
    r = adapter.send(request, **kwargs)
  File "/usr/lib/python3.7/site-packages/requests/adapters.py", line 498, in send
    raise ConnectionError(err, request=request)
requests.exceptions.ConnectionError: ('Connection aborted.', ConnectionResetError(104, 'Forbindelsen brudt i den anden ende'))
